
[2020-12-12 22:56:35,287-test_log-ERROR]: [Error in logger_base] msg: [Errno 2] No such file or directory: ''
Traceback (most recent call last):
  File "e:\PROJECT\python\SYNS\logger_base.py", line 37, in wrapper
    fn(*args)
  File "e:\PROJECT\python\SYNS\synapse_UI.py", line 303, in shift_analysis
    shift_roi.analysis(shift_list,template_file,out_list,expand_pixel=enlarge_pixel)
  File "e:\PROJECT\python\SYNS\shift_roi.py", line 308, in analysis
    roi2 = ImagejRoi.fromfile(roiname)
  File "C:\Users\ZLY\AppData\Local\Programs\Python\Python38\lib\site-packages\roifile\roifile.py", line 312, in fromfile
    with open(filename, 'rb') as fh:
FileNotFoundError: [Errno 2] No such file or directory: ''

[2020-12-12 22:56:35,287-test_log-ERROR]: [Error in logger_base] msg: [Errno 2] No such file or directory: ''
Traceback (most recent call last):
  File "e:\PROJECT\python\SYNS\logger_base.py", line 37, in wrapper
    fn(*args)
  File "e:\PROJECT\python\SYNS\synapse_UI.py", line 303, in shift_analysis
    shift_roi.analysis(shift_list,template_file,out_list,expand_pixel=enlarge_pixel)
  File "e:\PROJECT\python\SYNS\shift_roi.py", line 308, in analysis
    roi2 = ImagejRoi.fromfile(roiname)
  File "C:\Users\ZLY\AppData\Local\Programs\Python\Python38\lib\site-packages\roifile\roifile.py", line 312, in fromfile
    with open(filename, 'rb') as fh:
FileNotFoundError: [Errno 2] No such file or directory: ''

[2020-12-12 22:56:35,287-test_log-ERROR]: [Error in logger_base] msg: [Errno 2] No such file or directory: ''
Traceback (most recent call last):
  File "e:\PROJECT\python\SYNS\logger_base.py", line 37, in wrapper
    fn(*args)
  File "e:\PROJECT\python\SYNS\synapse_UI.py", line 303, in shift_analysis
    shift_roi.analysis(shift_list,template_file,out_list,expand_pixel=enlarge_pixel)
  File "e:\PROJECT\python\SYNS\shift_roi.py", line 308, in analysis
    roi2 = ImagejRoi.fromfile(roiname)
  File "C:\Users\ZLY\AppData\Local\Programs\Python\Python38\lib\site-packages\roifile\roifile.py", line 312, in fromfile
    with open(filename, 'rb') as fh:
FileNotFoundError: [Errno 2] No such file or directory: ''

[2020-12-14 15:01:09,055-test_log-ERROR]: [Error in logger_base] msg: too many values to unpack (expected 2)
Traceback (most recent call last):
  File "e:\PROJECT\python\SYNS\logger_base.py", line 37, in wrapper
    fn(*args)
  File "e:\PROJECT\python\SYNS\synapse_UI.py", line 324, in target_analysis
    synapse_roi.analysis(template_file,target_list,out_list)
  File "e:\PROJECT\python\SYNS\synapse_roi.py", line 276, in analysis
    img_label=label_roi(img,template)
  File "e:\PROJECT\python\SYNS\synapse_roi.py", line 154, in label_roi
    height, width = img.shape
ValueError: too many values to unpack (expected 2)

[2020-12-14 15:01:09,055-test_log-ERROR]: [Error in logger_base] msg: too many values to unpack (expected 2)
Traceback (most recent call last):
  File "e:\PROJECT\python\SYNS\logger_base.py", line 37, in wrapper
    fn(*args)
  File "e:\PROJECT\python\SYNS\synapse_UI.py", line 324, in target_analysis
    synapse_roi.analysis(template_file,target_list,out_list)
  File "e:\PROJECT\python\SYNS\synapse_roi.py", line 276, in analysis
    img_label=label_roi(img,template)
  File "e:\PROJECT\python\SYNS\synapse_roi.py", line 154, in label_roi
    height, width = img.shape
ValueError: too many values to unpack (expected 2)

[2020-12-14 15:01:09,055-test_log-ERROR]: [Error in logger_base] msg: too many values to unpack (expected 2)
Traceback (most recent call last):
  File "e:\PROJECT\python\SYNS\logger_base.py", line 37, in wrapper
    fn(*args)
  File "e:\PROJECT\python\SYNS\synapse_UI.py", line 324, in target_analysis
    synapse_roi.analysis(template_file,target_list,out_list)
  File "e:\PROJECT\python\SYNS\synapse_roi.py", line 276, in analysis
    img_label=label_roi(img,template)
  File "e:\PROJECT\python\SYNS\synapse_roi.py", line 154, in label_roi
    height, width = img.shape
ValueError: too many values to unpack (expected 2)

[2020-12-14 15:02:30,760-test_log-ERROR]: [Error in logger_base] msg: name 'u' is not defined
Traceback (most recent call last):
  File "e:\PROJECT\python\SYNS\logger_base.py", line 37, in wrapper
    fn(*args)
  File "e:\PROJECT\python\SYNS\synapse_UI.py", line 324, in target_analysis
    synapse_roi.analysis(template_file,target_list,out_list)
  File "e:\PROJECT\python\SYNS\synapse_roi.py", line 283, in analysis
    img_skeleton=branch_sklenton(img)
  File "e:\PROJECT\python\SYNS\synapse_roi.py", line 136, in branch_sklenton
    fil.analyze_skeletons(branch_thresh=30* u.pix, skel_thresh=30 * u.pix, prune_criteria='length')
NameError: name 'u' is not defined
